<?xml version="1.0" encoding="utf-8"?>
<robot name="wheelchair" path="/data/home/tianrun/wheel_chair_planning/resources/robot/wheelchair/wheelchair_base_decomposed.urdf">
	<material name="silver">
		<color rgba="0.700 0.700 0.700 1.000"></color>
	</material>
	<material name="Black">
		<color rgba="0.0 0.0 0.0 1.0"></color>
	</material>
	<material name="Red">
		<color rgba="0.8 0.0 0.0 1.0"></color>
	</material>
	<material name="White">
		<color rgba="1.0 1.0 1.0 1.0"></color>
	</material>
	<material name="Silver">
		<color rgba="0.753 0.753 0.753 1.0"></color>
	</material>
	<transmission name="Revolute 1_tran">
		<type>transmission_interface/SimpleTransmission</type>
		<joint name="Revolute 1">
			<hardwareInterface>hardware_interface/EffortJointInterface</hardwareInterface>
		</joint>
		<actuator name="Revolute 1_actr">
			<hardwareInterface>hardware_interface/EffortJointInterface</hardwareInterface>
			<mechanicalReduction>1</mechanicalReduction>
		</actuator>
	</transmission>
	<transmission name="Revolute 2_tran">
		<type>transmission_interface/SimpleTransmission</type>
		<joint name="Revolute 2">
			<hardwareInterface>hardware_interface/EffortJointInterface</hardwareInterface>
		</joint>
		<actuator name="Revolute 2_actr">
			<hardwareInterface>hardware_interface/EffortJointInterface</hardwareInterface>
			<mechanicalReduction>1</mechanicalReduction>
		</actuator>
	</transmission>
	<transmission name="Revolute 3_tran">
		<type>transmission_interface/SimpleTransmission</type>
		<joint name="Revolute 3">
			<hardwareInterface>hardware_interface/EffortJointInterface</hardwareInterface>
		</joint>
		<actuator name="Revolute 3_actr">
			<hardwareInterface>hardware_interface/EffortJointInterface</hardwareInterface>
			<mechanicalReduction>1</mechanicalReduction>
		</actuator>
	</transmission>
	<transmission name="Revolute 4_tran">
		<type>transmission_interface/SimpleTransmission</type>
		<joint name="Revolute 4">
			<hardwareInterface>hardware_interface/EffortJointInterface</hardwareInterface>
		</joint>
		<actuator name="Revolute 4_actr">
			<hardwareInterface>hardware_interface/EffortJointInterface</hardwareInterface>
			<mechanicalReduction>1</mechanicalReduction>
		</actuator>
	</transmission>
	<transmission name="Revolute 5_tran">
		<type>transmission_interface/SimpleTransmission</type>
		<joint name="Revolute 5">
			<hardwareInterface>hardware_interface/EffortJointInterface</hardwareInterface>
		</joint>
		<actuator name="Revolute 5_actr">
			<hardwareInterface>hardware_interface/EffortJointInterface</hardwareInterface>
			<mechanicalReduction>1</mechanicalReduction>
		</actuator>
	</transmission>
	<transmission name="tran1">
		<type>transmission_interface/SimpleTransmission</type>
		<joint name="joint1">
			<hardwareInterface>hardware_interface/PositionJointInterface</hardwareInterface>
		</joint>
		<actuator name="motor1">
			<hardwareInterface>hardware_interface/PositionJointInterface</hardwareInterface>
			<mechanicalReduction>100</mechanicalReduction>
		</actuator>
	</transmission>
	<transmission name="tran2">
		<type>transmission_interface/SimpleTransmission</type>
		<joint name="joint2">
			<hardwareInterface>hardware_interface/PositionJointInterface</hardwareInterface>
		</joint>
		<actuator name="motor2">
			<hardwareInterface>hardware_interface/PositionJointInterface</hardwareInterface>
			<mechanicalReduction>100</mechanicalReduction>
		</actuator>
	</transmission>
	<transmission name="tran3">
		<type>transmission_interface/SimpleTransmission</type>
		<joint name="joint3">
			<hardwareInterface>hardware_interface/PositionJointInterface</hardwareInterface>
		</joint>
		<actuator name="motor3">
			<hardwareInterface>hardware_interface/PositionJointInterface</hardwareInterface>
			<mechanicalReduction>100</mechanicalReduction>
		</actuator>
	</transmission>
	<transmission name="tran4">
		<type>transmission_interface/SimpleTransmission</type>
		<joint name="joint4">
			<hardwareInterface>hardware_interface/PositionJointInterface</hardwareInterface>
		</joint>
		<actuator name="motor4">
			<hardwareInterface>hardware_interface/PositionJointInterface</hardwareInterface>
			<mechanicalReduction>100</mechanicalReduction>
		</actuator>
	</transmission>
	<transmission name="tran5">
		<type>transmission_interface/SimpleTransmission</type>
		<joint name="joint5">
			<hardwareInterface>hardware_interface/PositionJointInterface</hardwareInterface>
		</joint>
		<actuator name="motor5">
			<hardwareInterface>hardware_interface/PositionJointInterface</hardwareInterface>
			<mechanicalReduction>100</mechanicalReduction>
		</actuator>
	</transmission>
	<transmission name="tran6">
		<type>transmission_interface/SimpleTransmission</type>
		<joint name="joint6">
			<hardwareInterface>hardware_interface/PositionJointInterface</hardwareInterface>
		</joint>
		<actuator name="motor6">
			<hardwareInterface>hardware_interface/PositionJointInterface</hardwareInterface>
			<mechanicalReduction>100</mechanicalReduction>
		</actuator>
	</transmission>
	<transmission name="tran7">
		<type>transmission_interface/SimpleTransmission</type>
		<joint name="joint7">
			<hardwareInterface>hardware_interface/PositionJointInterface</hardwareInterface>
		</joint>
		<actuator name="motor7">
			<hardwareInterface>hardware_interface/PositionJointInterface</hardwareInterface>
			<mechanicalReduction>100</mechanicalReduction>
		</actuator>
	</transmission>
	<transmission name="drive_joint_trans">
		<type>transmission_interface/SimpleTransmission</type>
		<joint name="drive_joint">
			<hardwareInterface>hardware_interface/PositionJointInterface</hardwareInterface>
		</joint>
		<actuator name="drive_joint_motor">
			<hardwareInterface>hardware_interface/PositionJointInterface</hardwareInterface>
			<mechanicalReduction>1</mechanicalReduction>
		</actuator>
	</transmission>
	<ros2_control name="GazeboSystem" type="system">
		<hardware>
			<plugin>gazebo_ros2_control/GazeboSystem</plugin>
		</hardware>
		<joint name="Revolute 1">
			<command_interface name="position">
				<param name="min">0.0</param>
				<param name="max">1.570796</param>
			</command_interface>
			<state_interface name="position"></state_interface>
			<state_interface name="velocity"></state_interface>
			<state_interface name="effort"></state_interface>
		</joint>
		<joint name="Revolute 2">
			<command_interface name="position"></command_interface>
			<state_interface name="position"></state_interface>
			<state_interface name="velocity"></state_interface>
			<state_interface name="effort"></state_interface>
		</joint>
		<joint name="Revolute 3">
			<command_interface name="position"></command_interface>
			<state_interface name="position"></state_interface>
			<state_interface name="velocity"></state_interface>
			<state_interface name="effort"></state_interface>
		</joint>
		<joint name="Revolute 4">
			<command_interface name="position"></command_interface>
			<state_interface name="position"></state_interface>
			<state_interface name="velocity"></state_interface>
			<state_interface name="effort"></state_interface>
		</joint>
		<joint name="Revolute 5">
			<command_interface name="position"></command_interface>
			<state_interface name="position"></state_interface>
			<state_interface name="velocity"></state_interface>
			<state_interface name="effort"></state_interface>
		</joint>
	</ros2_control>
	<ros2_control name="uf_robot_hardware/UFRobotSystemHardware" type="system">
		<hardware>
			<plugin>uf_robot_hardware/UFRobotSystemHardware</plugin>
			<param name="hw_ns">xarm</param>
			<param name="velocity_control">False</param>
			<param name="prefix">P</param>
			<param name="robot_ip">R</param>
			<param name="report_type">normal</param>
			<param name="dof">7</param>
			<param name="baud_checkset">True</param>
			<param name="default_gripper_baud">2000000</param>
			<param name="robot_type">xarm</param>
			<param name="add_gripper">True</param>
			<param name="add_bio_gripper">False</param>
		</hardware>
		<joint name="joint1">
			<command_interface name="position">
				<param name="min">-6.283185307179586</param>
				<param name="max">6.283185307179586</param>
			</command_interface>
			<command_interface name="velocity">
				<param name="min">-3.14</param>
				<param name="max">3.14</param>
			</command_interface>
			<state_interface name="position"></state_interface>
			<state_interface name="velocity"></state_interface>
		</joint>
		<joint name="joint2">
			<command_interface name="position">
				<param name="min">-2.059</param>
				<param name="max">2.0944</param>
			</command_interface>
			<command_interface name="velocity">
				<param name="min">-3.14</param>
				<param name="max">3.14</param>
			</command_interface>
			<state_interface name="position"></state_interface>
			<state_interface name="velocity"></state_interface>
		</joint>
		<joint name="joint3">
			<command_interface name="position">
				<param name="min">-6.283185307179586</param>
				<param name="max">6.283185307179586</param>
			</command_interface>
			<command_interface name="velocity">
				<param name="min">-3.14</param>
				<param name="max">3.14</param>
			</command_interface>
			<state_interface name="position"></state_interface>
			<state_interface name="velocity"></state_interface>
		</joint>
		<joint name="joint4">
			<command_interface name="position">
				<param name="min">-0.19198</param>
				<param name="max">3.927</param>
			</command_interface>
			<command_interface name="velocity">
				<param name="min">-3.14</param>
				<param name="max">3.14</param>
			</command_interface>
			<state_interface name="position"></state_interface>
			<state_interface name="velocity"></state_interface>
		</joint>
		<joint name="joint5">
			<command_interface name="position">
				<param name="min">-6.283185307179586</param>
				<param name="max">6.283185307179586</param>
			</command_interface>
			<command_interface name="velocity">
				<param name="min">-3.14</param>
				<param name="max">3.14</param>
			</command_interface>
			<state_interface name="position"></state_interface>
			<state_interface name="velocity"></state_interface>
		</joint>
		<joint name="joint6">
			<command_interface name="position">
				<param name="min">-1.69297</param>
				<param name="max">3.141592653589793</param>
			</command_interface>
			<command_interface name="velocity">
				<param name="min">-3.14</param>
				<param name="max">3.14</param>
			</command_interface>
			<state_interface name="position"></state_interface>
			<state_interface name="velocity"></state_interface>
		</joint>
		<joint name="joint7">
			<command_interface name="position">
				<param name="min">-6.283185307179586</param>
				<param name="max">6.283185307179586</param>
			</command_interface>
			<command_interface name="velocity">
				<param name="min">-3.14</param>
				<param name="max">3.14</param>
			</command_interface>
			<state_interface name="position"></state_interface>
			<state_interface name="velocity"></state_interface>
		</joint>
	</ros2_control>
	<gazebo reference="base_link">
		<material>Gazebo/Silver</material>
		<mu1>0.2</mu1>
		<mu2>0.2</mu2>
		<selfCollide>true</selfCollide>
		<gravity>true</gravity>
	</gazebo>
	<gazebo reference="lip_1">
		<material>Gazebo/Silver</material>
		<mu1>0.2</mu1>
		<mu2>0.2</mu2>
		<selfCollide>true</selfCollide>
	</gazebo>
	<gazebo reference="front_right_1">
		<material>Gazebo/Silver</material>
		<mu1>0.2</mu1>
		<mu2>0.2</mu2>
		<selfCollide>true</selfCollide>
	</gazebo>
	<gazebo reference="front_left_1">
		<material>Gazebo/Silver</material>
		<mu1>0.2</mu1>
		<mu2>0.2</mu2>
		<selfCollide>true</selfCollide>
	</gazebo>
	<gazebo reference="back_right_1">
		<material>Gazebo/Silver</material>
		<mu1>0.2</mu1>
		<mu2>0.2</mu2>
		<selfCollide>true</selfCollide>
	</gazebo>
	<gazebo reference="back_left_1">
		<material>Gazebo/Silver</material>
		<mu1>0.2</mu1>
		<mu2>0.2</mu2>
		<selfCollide>true</selfCollide>
	</gazebo>
	<gazebo reference="laser_left">
		<material>Gazebo/Blue</material>
	</gazebo>
	<gazebo reference="laser_right">
		<material>Gazebo/Blue</material>
	</gazebo>
	<gazebo reference="link_base">
		<selfCollide>true</selfCollide>
	</gazebo>
	<gazebo reference="link1">
		<selfCollide>true</selfCollide>
	</gazebo>
	<gazebo reference="link2">
		<selfCollide>true</selfCollide>
	</gazebo>
	<gazebo reference="link3">
		<selfCollide>true</selfCollide>
	</gazebo>
	<gazebo reference="link4">
		<selfCollide>true</selfCollide>
	</gazebo>
	<gazebo reference="link5">
		<selfCollide>true</selfCollide>
	</gazebo>
	<gazebo reference="link6">
		<selfCollide>true</selfCollide>
	</gazebo>
	<gazebo reference="link7">
		<selfCollide>true</selfCollide>
	</gazebo>
	<gazebo reference="xarm_gripper_base_link">
		<selfCollide>false</selfCollide>
	</gazebo>
	<gazebo reference="left_outer_knuckle">
		<selfCollide>false</selfCollide>
	</gazebo>
	<gazebo reference="left_finger">
		<selfCollide>false</selfCollide>
	</gazebo>
	<gazebo reference="left_inner_knuckle">
		<selfCollide>false</selfCollide>
	</gazebo>
	<gazebo reference="right_outer_knuckle">
		<selfCollide>false</selfCollide>
	</gazebo>
	<gazebo reference="right_finger">
		<selfCollide>false</selfCollide>
	</gazebo>
	<gazebo reference="right_inner_knuckle">
		<selfCollide>false</selfCollide>
	</gazebo>
	<gazebo>
		<plugin filename="libgazebo_mimic_joint_plugin.so" name="gz::sim::systems::GazeboMimicJointPlugin">
			<joint>drive_joint</joint>
			<mimicJoint>left_finger_joint</mimicJoint>
			<hasPID></hasPID>
			<multiplier>1.0</multiplier>
			<offset>0</offset>
			<sensitiveness>0.0</sensitiveness>
			<maxEffort>10.0</maxEffort>
		</plugin>
	</gazebo>
	<gazebo>
		<plugin filename="libgazebo_mimic_joint_plugin.so" name="gz::sim::systems::GazeboMimicJointPlugin">
			<joint>drive_joint</joint>
			<mimicJoint>left_inner_knuckle_joint</mimicJoint>
			<hasPID></hasPID>
			<multiplier>1.0</multiplier>
			<offset>0</offset>
			<sensitiveness>0.0</sensitiveness>
			<maxEffort>10.0</maxEffort>
		</plugin>
	</gazebo>
	<gazebo>
		<plugin filename="libgazebo_mimic_joint_plugin.so" name="gz::sim::systems::GazeboMimicJointPlugin">
			<joint>drive_joint</joint>
			<mimicJoint>right_outer_knuckle_joint</mimicJoint>
			<hasPID></hasPID>
			<multiplier>1.0</multiplier>
			<offset>0</offset>
			<sensitiveness>0.0</sensitiveness>
			<maxEffort>10.0</maxEffort>
		</plugin>
	</gazebo>
	<gazebo>
		<plugin filename="libgazebo_mimic_joint_plugin.so" name="gz::sim::systems::GazeboMimicJointPlugin">
			<joint>drive_joint</joint>
			<mimicJoint>right_finger_joint</mimicJoint>
			<hasPID></hasPID>
			<multiplier>1.0</multiplier>
			<offset>0</offset>
			<sensitiveness>0.0</sensitiveness>
			<maxEffort>10.0</maxEffort>
		</plugin>
	</gazebo>
	<gazebo>
		<plugin filename="libgazebo_mimic_joint_plugin.so" name="gz::sim::systems::GazeboMimicJointPlugin">
			<joint>drive_joint</joint>
			<mimicJoint>right_inner_knuckle_joint</mimicJoint>
			<hasPID></hasPID>
			<multiplier>1.0</multiplier>
			<offset>0</offset>
			<sensitiveness>0.0</sensitiveness>
			<maxEffort>10.0</maxEffort>
		</plugin>
	</gazebo>
	<link name="base_link">
		<inertial>
			<origin rpy="0 0 0" xyz="0 0 0"></origin>
			<mass value="332.01068376069776"></mass>
			<inertia ixx="28.453256" ixy="0.242673" ixz="0.389285" iyy="23.493643" iyz="-7.755885" izz="18.780017"></inertia>
		</inertial>
		<visual>
			<origin rpy="0 0 0" xyz="0 0 0"></origin>
			<geometry>
				<mesh filename="package://meshes/base_fixed.stl"></mesh>
			</geometry>
			<material name="silver"></material>
		</visual>
		<collision>
			<geometry>
				<sphere radius="0.332482"></sphere>
			</geometry>
			<origin xyz="0.3722078470504284 0.13519129070281982 0.2183835018298626" rpy="0 0 0"></origin>
		</collision>
		<collision>
			<geometry>
				<sphere radius="0.316001"></sphere>
			</geometry>
			<origin xyz="0.38814584705042837 -0.13579670929718018 0.2050225018298626" rpy="0 0 0"></origin>
		</collision>
		<collision>
			<geometry>
				<sphere radius="0.324506"></sphere>
			</geometry>
			<origin xyz="-0.009226733938694 0.003671177332878113 0.636058002699852" rpy="0 0 0"></origin>
		</collision>
		<collision>
			<geometry>
				<sphere radius="0.324877"></sphere>
			</geometry>
			<origin xyz="-0.012697733938694 0.10704317733287812 0.286539002699852" rpy="0 0 0"></origin>
		</collision>
		<collision>
			<geometry>
				<sphere radius="0.329858"></sphere>
			</geometry>
			<origin xyz="-0.012695733938694 -0.1658778226671219 0.340869002699852" rpy="0 0 0"></origin>
		</collision>
		<collision>
			<geometry>
				<sphere radius="0.208522"></sphere>
			</geometry>
			<origin xyz="-0.17647868028450012 -0.04289342681837082 0.1448515182526111" rpy="0 0 0"></origin>
		</collision>
		<collision>
			<geometry>
				<sphere radius="0.206641"></sphere>
			</geometry>
			<origin xyz="-0.17758668028450011 0.17586857318162918 0.23331651825261118" rpy="0 0 0"></origin>
		</collision>
		<collision>
			<geometry>
				<sphere radius="0.2078"></sphere>
			</geometry>
			<origin xyz="-0.17945568028450012 -0.07667342681837082 0.40608751825261113" rpy="0 0 0"></origin>
		</collision>
		<collision>
			<geometry>
				<sphere radius="0.212631"></sphere>
			</geometry>
			<origin xyz="-0.18498768028450013 0.1429855731816292 0.6293555182526112" rpy="0 0 0"></origin>
		</collision>
		<collision>
			<geometry>
				<sphere radius="0.223721"></sphere>
			</geometry>
			<origin xyz="-0.19037168028450013 -0.15409842681837083 0.7733945182526112" rpy="0 0 0"></origin>
		</collision>
		<collision>
			<geometry>
				<sphere radius="0.202272"></sphere>
			</geometry>
			<origin xyz="-0.19546968028450012 0.11988457318162918 1.009325518252611" rpy="0 0 0"></origin>
		</collision>
		<collision>
			<geometry>
				<sphere radius="0.186615"></sphere>
			</geometry>
			<origin xyz="-0.19541868028450013 -0.1595244268183708 1.1681375182526113" rpy="0 0 0"></origin>
		</collision>
		<collision>
			<geometry>
				<sphere radius="0.17986"></sphere>
			</geometry>
			<origin xyz="-0.19538668028450012 0.05005357318162918 1.2666575182526112" rpy="0 0 0"></origin>
		</collision>
		<collision>
			<geometry>
				<sphere radius="0.139779"></sphere>
			</geometry>
			<origin xyz="0.338828267157793 0.25729005337429045 0.46665168565177917" rpy="0 0 0"></origin>
		</collision>
		<collision>
			<geometry>
				<sphere radius="0.139376"></sphere>
			</geometry>
			<origin xyz="0.36451126715779303 0.27085405337429047 0.6432596856517792" rpy="0 0 0"></origin>
		</collision>
		<collision>
			<geometry>
				<sphere radius="0.12087"></sphere>
			</geometry>
			<origin xyz="0.19479326715779305 0.23972905337429046 0.5053266856517792" rpy="0 0 0"></origin>
		</collision>
		<collision>
			<geometry>
				<sphere radius="0.109746"></sphere>
			</geometry>
			<origin xyz="0.18820626715779304 0.2609360533742905 0.6565596856517791" rpy="0 0 0"></origin>
		</collision>
		<collision>
			<geometry>
				<sphere radius="0.239739"></sphere>
			</geometry>
			<origin xyz="0.27248237068486214 0.03849827093315125 0.4986336706085205" rpy="0 0 0"></origin>
		</collision>
		<collision>
			<geometry>
				<sphere radius="0.238208"></sphere>
			</geometry>
			<origin xyz="0.23655937068486213 -0.14613372906684874 0.5780156706085205" rpy="0 0 0"></origin>
		</collision>
		<collision>
			<geometry>
				<sphere radius="0.200216"></sphere>
			</geometry>
			<origin xyz="0.40816537068486214 -0.18669172906684875 0.6533586706085205" rpy="0 0 0"></origin>
		</collision>
	</link>
	<link name="front_right_1">
		<inertial>
			<origin rpy="0 0 0" xyz="0 -0.013 0"></origin>
			<mass value="21.702165340628166"></mass>
			<inertia ixx="0.094704" ixy="0.0" ixz="0.0" iyy="0.176378" iyz="0.0" izz="0.094704"></inertia>
		</inertial>
		<visual>
			<origin rpy="0 0 0" xyz="0 0 0"></origin>
			<geometry>
				<mesh filename="package://meshes/front.stl"></mesh>
			</geometry>
			<material name="silver"></material>
		</visual>
		<collision>
			<geometry>
				<sphere radius="0.127501"></sphere>
			</geometry>
			<origin xyz="-6.282763004302979e-06 -0.01298513708126545 2.724687576293945e-06" rpy="0 0 0"></origin>
		</collision>
		<collision>
			<geometry>
				<sphere radius="0.126117"></sphere>
			</geometry>
			<origin xyz="0.015429717236995696 -0.01298713708126545 -0.007360275312423706" rpy="0 0 0"></origin>
		</collision>
	</link>
	<link name="front_left_1">
		<inertial>
			<origin rpy="0 0 0" xyz="0 0.013 0"></origin>
			<mass value="21.702165340628156"></mass>
			<inertia ixx="0.094704" ixy="0.0" ixz="0.0" iyy="0.176378" iyz="0.0" izz="0.094704"></inertia>
		</inertial>
		<visual>
			<origin rpy="0 0 3.14159" xyz="0 0 0"></origin>
			<geometry>
				<mesh filename="package://meshes/front.stl"></mesh>
			</geometry>
			<material name="silver"></material>
		</visual>
		<collision>
			<geometry>
				<sphere radius="0.135528"></sphere>
			</geometry>
			<origin xyz="0.00048167177835860644 0.012936477314845242 -0.007443741221150302" rpy="0 0 0"></origin>
		</collision>
		<collision>
			<geometry>
				<sphere radius="0.135648"></sphere>
			</geometry>
			<origin xyz="0.0013236717783586065 0.012878477314845243 0.012202258778849699" rpy="0 0 0"></origin>
		</collision>
	</link>
	<link name="back_right_1">
		<inertial>
			<origin rpy="0 0 0" xyz="0 -0.0406 0"></origin>
			<mass value="17.247382273323833"></mass>
			<inertia ixx="0.076880" ixy="0.0" ixz="0.0" iyy="0.127230" iyz="0.0" izz="0.076880"></inertia>
		</inertial>
		<visual>
			<origin rpy="0 0 0" xyz="0 0 0"></origin>
			<geometry>
				<mesh filename="package://meshes/back.stl"></mesh>
			</geometry>
			<material name="silver"></material>
		</visual>
		<collision>
			<geometry>
				<sphere radius="0.135849"></sphere>
			</geometry>
			<origin xyz="5.143495080629681e-05 -0.04015354327716007 0.0004872155048258604" rpy="0 0 0"></origin>
		</collision>
	</link>
	<link name="back_left_1">
		<inertial>
			<origin rpy="0 0 0" xyz="0 0.0406 0"></origin>
			<mass value="17.247400849331317"></mass>
			<inertia ixx="0.076880" ixy="0.0" ixz="0.0" iyy="0.127230" iyz="0.0" izz="0.076880"></inertia>
		</inertial>
		<visual>
			<origin rpy="0 0 3.14159" xyz="0 0 0"></origin>
			<geometry>
				<mesh filename="package://meshes/back.stl"></mesh>
			</geometry>
			<material name="silver"></material>
		</visual>
		<collision>
			<geometry>
				<sphere radius="0.125902"></sphere>
			</geometry>
			<origin xyz="2.736604893386461e-05 0.04058021638275432 -8.409037518501282e-05" rpy="0 0 0"></origin>
		</collision>
	</link>
	<link name="link_base">
		<inertial>
			<origin rpy="0 0 0" xyz="-0.021131 -0.0016302 0.056488"></origin>
			<mass value="0.88556"></mass>
			<inertia ixx="0.0030595" ixy="0.00012259" ixz="-0.00062705" iyy="0.0037783" iyz="0.00027023" izz="0.0020125"></inertia>
		</inertial>
		<visual>
			<geometry>
				<mesh filename="package://meshes/link_base.stl"></mesh>
			</geometry>
			<origin rpy="0 0 0" xyz="0 0 0"></origin>
			<material name="White"></material>
		</visual>
		<collision>
			<geometry>
				<sphere radius="0.101154"></sphere>
			</geometry>
			<origin xyz="-0.004306574258565904 0.0003400037252902985 0.06791800555145787" rpy="0 0 0"></origin>
		</collision>
	</link>
	<link name="link1">
		<inertial>
			<origin rpy="0 0 0" xyz="-0.0002 0.02905 -0.01233"></origin>
			<mass value="2.382"></mass>
			<inertia ixx="0.0056905" ixy="-1.579e-05" ixz="5.125e-06" iyy="0.0049566" iyz="-0.000873378" izz="0.003316654"></inertia>
		</inertial>
		<visual>
			<geometry>
				<mesh filename="package://meshes/link1.stl"></mesh>
			</geometry>
			<origin rpy="0 0 0" xyz="0 0 0"></origin>
			<material name="White"></material>
		</visual>
		<collision>
			<geometry>
				<sphere radius="0.103746"></sphere>
			</geometry>
			<origin xyz="-0.0002654442278606843 0.018507836469288254 -0.03509712153635607" rpy="0 0 0"></origin>
		</collision>
	</link>
	<link name="link2">
		<inertial>
			<origin rpy="0 0 0" xyz="0.00022 -0.12856 0.01735"></origin>
			<mass value="1.869"></mass>
			<inertia ixx="0.0095989" ixy="1.541e-06" ixz="5.56e-06" iyy="0.00382472" iyz="-0.00317156" izz="0.007565669"></inertia>
		</inertial>
		<visual>
			<geometry>
				<mesh filename="package://meshes/link2.stl"></mesh>
			</geometry>
			<origin rpy="0 0 0" xyz="0 0 0"></origin>
			<material name="White"></material>
		</visual>
		<collision>
			<geometry>
				<sphere radius="0.078939"></sphere>
			</geometry>
			<origin xyz="6.81895470619202e-06 -0.13765490535211564 0.015358753489375116" rpy="0 0 0"></origin>
		</collision>
		<collision>
			<geometry>
				<sphere radius="0.078743"></sphere>
			</geometry>
			<origin xyz="-1.1181045293807984e-05 -0.027644905352115633 0.07137275348937511" rpy="0 0 0"></origin>
		</collision>
		<collision>
			<geometry>
				<sphere radius="0.081115"></sphere>
			</geometry>
			<origin xyz="9.818954706192012e-06 -0.10140390535211563 0.03988275348937512" rpy="0 0 0"></origin>
		</collision>
	</link>
	<link name="link3">
		<inertial>
			<origin rpy="0 0 0" xyz="0.0466 -0.02463 -0.00768"></origin>
			<mass value="1.6383"></mass>
			<inertia ixx="0.00310955" ixy="0.00030837" ixz="-0.00058453" iyy="0.00264483" iyz="0.000338893" izz="0.0026624"></inertia>
		</inertial>
		<visual>
			<geometry>
				<mesh filename="package://meshes/link3.stl"></mesh>
			</geometry>
			<origin rpy="0 0 0" xyz="0 0 0"></origin>
			<material name="White"></material>
		</visual>
		<collision>
			<geometry>
				<sphere radius="0.082032"></sphere>
			</geometry>
			<origin xyz="0.01831963247656822 0.00017922421669960018 -0.045968335240006444" rpy="0 0 0"></origin>
		</collision>
		<collision>
			<geometry>
				<sphere radius="0.079976"></sphere>
			</geometry>
			<origin xyz="0.04620263247656822 -0.0063827757833004 -0.007560335240006447" rpy="0 0 0"></origin>
		</collision>
	</link>
	<link name="link4">
		<inertial>
			<origin rpy="0 0 0" xyz="0.07047 -0.11575 0.012"></origin>
			<mass value="1.7269"></mass>
			<inertia ixx="0.005889" ixy="0.00137112" ixz="0.00088143" iyy="0.00359703" iyz="-0.001762155" izz="0.00543244"></inertia>
		</inertial>
		<visual>
			<geometry>
				<mesh filename="package://meshes/link4.stl"></mesh>
			</geometry>
			<origin rpy="0 0 0" xyz="0 0 0"></origin>
			<material name="White"></material>
		</visual>
		<collision>
			<geometry>
				<sphere radius="0.077787"></sphere>
			</geometry>
			<origin xyz="0.07031486234366893 -0.1183887701896429 0.015032635922193529" rpy="0 0 0"></origin>
		</collision>
		<collision>
			<geometry>
				<sphere radius="0.082288"></sphere>
			</geometry>
			<origin xyz="0.06117586234366894 -0.0855117701896429 0.03594063592219353" rpy="0 0 0"></origin>
		</collision>
		<collision>
			<geometry>
				<sphere radius="0.069004"></sphere>
			</geometry>
			<origin xyz="0.018659862343668936 -0.01491777018964291 0.06634363592219353" rpy="0 0 0"></origin>
		</collision>
	</link>
	<link name="link5">
		<inertial>
			<origin rpy="0 0 0" xyz="-0.00032 0.01604 -0.026"></origin>
			<mass value="1.3203"></mass>
			<inertia ixx="0.00534665" ixy="1.5117e-05" ixz="-3.69e-07" iyy="0.0049779" iyz="-0.00022132" izz="0.0013624"></inertia>
		</inertial>
		<visual>
			<geometry>
				<mesh filename="package://meshes/link5.stl"></mesh>
			</geometry>
			<origin rpy="0 0 0" xyz="0 0 0"></origin>
			<material name="White"></material>
		</visual>
		<collision>
			<geometry>
				<sphere radius="0.070928"></sphere>
			</geometry>
			<origin xyz="-1.4152219827174987e-06 0.008840182681256204 -0.13324678966543646" rpy="0 0 0"></origin>
		</collision>
		<collision>
			<geometry>
				<sphere radius="0.071552"></sphere>
			</geometry>
			<origin xyz="-0.0003494152219827175 0.025022182681256205 -0.06803078966543645" rpy="0 0 0"></origin>
		</collision>
		<collision>
			<geometry>
				<sphere radius="0.067511"></sphere>
			</geometry>
			<origin xyz="-0.0005244152219827174 0.04318818268125621 -0.012698789665436458" rpy="0 0 0"></origin>
		</collision>
	</link>
	<link name="link6">
		<inertial>
			<origin rpy="0 0 0" xyz="0.06469 0.03278 0.02141"></origin>
			<mass value="1.325"></mass>
			<inertia ixx="0.0014745" ixy="-0.000488" ixz="0.0002953" iyy="0.0019037" iyz="0.00014749" izz="0.0023652"></inertia>
		</inertial>
		<visual>
			<geometry>
				<mesh filename="package://meshes/link6.stl"></mesh>
			</geometry>
			<origin rpy="0 0 0" xyz="0 0 0"></origin>
			<material name="White"></material>
		</visual>
		<collision>
			<geometry>
				<sphere radius="0.063881"></sphere>
			</geometry>
			<origin xyz="0.07141181972372532 0.02062064614546299 0.0013090134370326995" rpy="0 0 0"></origin>
		</collision>
		<collision>
			<geometry>
				<sphere radius="0.059529"></sphere>
			</geometry>
			<origin xyz="0.01657781972372532 0.00298864614546299 0.0167010134370327" rpy="0 0 0"></origin>
		</collision>
	</link>
	<link name="link7">
		<inertial>
			<origin rpy="0 0 0" xyz="0 -0.00677 -0.01098"></origin>
			<mass value="0.17"></mass>
			<inertia ixx="9.3e-05" ixy="-0.0" ixz="-0.0" iyy="5.87e-05" iyz="-3.6e-06" izz="0.000132"></inertia>
		</inertial>
		<visual>
			<geometry>
				<mesh filename="package://meshes/link7.stl"></mesh>
			</geometry>
			<origin rpy="0 0 0" xyz="0 0 0"></origin>
			<material name="Silver"></material>
		</visual>
		<collision>
			<geometry>
				<sphere radius="0.040936"></sphere>
			</geometry>
			<origin xyz="0.00048996233355999 -0.0007756241878271106 -0.013500000350177288" rpy="0 0 0"></origin>
		</collision>
		<collision>
			<geometry>
				<sphere radius="0.029515"></sphere>
			</geometry>
			<origin xyz="-0.00582203766644001 -0.02685362418782711 -0.013500000350177288" rpy="0 0 0"></origin>
		</collision>
	</link>
	<link name="link_eef">
		<visual>
			<geometry>
				<mesh filename="package://meshes/d435_with_cam_stand.stl"></mesh>
			</geometry>
			<origin rpy="0 0 0" xyz="0 0 0"></origin>
			<material name="Silver"></material>
		</visual>
		<collision>
			<geometry>
				<sphere radius="0.037207"></sphere>
			</geometry>
			<origin xyz="0.05285972737101581 -0.018828776604613164 0.013315807426587566" rpy="0 0 0"></origin>
		</collision>
		<collision>
			<geometry>
				<sphere radius="0.037909"></sphere>
			</geometry>
			<origin xyz="0.05127572737101581 0.023463223395386836 0.013091807426587566" rpy="0 0 0"></origin>
		</collision>
		<collision>
			<geometry>
				<sphere radius="0.031424"></sphere>
			</geometry>
			<origin xyz="0.00040372737101580444 0.017058223395386835 0.0062848074265875655" rpy="0 0 0"></origin>
		</collision>
		<collision>
			<geometry>
				<sphere radius="0.03107"></sphere>
			</geometry>
			<origin xyz="0.0015417273710158046 -0.025021776604613164 0.005989807426587565" rpy="0 0 0"></origin>
		</collision>
		<collision>
			<geometry>
				<sphere radius="0.0284"></sphere>
			</geometry>
			<origin xyz="-0.023105272628984194 0.00029022339538683605 0.003145807426587566" rpy="0 0 0"></origin>
		</collision>
	</link>
	<link name="xarm_gripper_base_link">
		<inertial>
			<origin rpy="0 0 0" xyz="-0.00065489 -0.0018497 0.048028"></origin>
			<mass value="0.54156"></mass>
			<inertia ixx="0.00047106" ixy="3.9292E-07" ixz="2.6537E-06" iyy="0.00033072" iyz="-1.0975E-05" izz="0.00025642"></inertia>
		</inertial>
		<visual>
			<geometry>
				<mesh filename="package://meshes/base_link.stl"></mesh>
			</geometry>
			<origin rpy="0 0 0" xyz="0 0 0"></origin>
			<material name="White"></material>
		</visual>
		<collision>
			<geometry>
				<sphere radius="0.059837"></sphere>
			</geometry>
			<origin xyz="-0.002970734363079071 -2.0540167093276977e-06 0.01976423348072171" rpy="0 0 0"></origin>
		</collision>
		<collision>
			<geometry>
				<sphere radius="0.032745"></sphere>
			</geometry>
			<origin xyz="-0.01597420570626855 -0.013141915039658546 0.07577663155782223" rpy="0 0 0"></origin>
		</collision>
		<collision>
			<geometry>
				<sphere radius="0.031388"></sphere>
			</geometry>
			<origin xyz="-0.015438205706268549 0.038458084960341456 0.07526863155782222" rpy="0 0 0"></origin>
		</collision>
		<collision>
			<geometry>
				<sphere radius="0.03117"></sphere>
			</geometry>
			<origin xyz="-0.015419205706268549 -0.03888691503965855 0.07520863155782223" rpy="0 0 0"></origin>
		</collision>
		<collision>
			<geometry>
				<sphere radius="0.03261"></sphere>
			</geometry>
			<origin xyz="-0.01596420570626855 0.014736084960341454 0.07463863155782223" rpy="0 0 0"></origin>
		</collision>
		<collision>
			<geometry>
				<sphere radius="0.028129"></sphere>
			</geometry>
			<origin xyz="0.009540986084461212 0.023296399898934905 0.08992908615863324" rpy="0 0 0"></origin>
		</collision>
		<collision>
			<geometry>
				<sphere radius="0.024271"></sphere>
			</geometry>
			<origin xyz="0.009765986084461211 0.037904399898934904 0.06529708615863324" rpy="0 0 0"></origin>
		</collision>
		<collision>
			<geometry>
				<sphere radius="0.023541"></sphere>
			</geometry>
			<origin xyz="0.016169986084461213 0.013227399898934906 0.06610508615863323" rpy="0 0 0"></origin>
		</collision>
		<collision>
			<geometry>
				<sphere radius="0.026365"></sphere>
			</geometry>
			<origin xyz="0.010424679345317185 -0.03400422910096097 0.06448836976158619" rpy="0 0 0"></origin>
		</collision>
		<collision>
			<geometry>
				<sphere radius="0.028215"></sphere>
			</geometry>
			<origin xyz="0.009532679345317185 -0.02342122910096097 0.08999936976158619" rpy="0 0 0"></origin>
		</collision>
		<collision>
			<geometry>
				<sphere radius="0.023513"></sphere>
			</geometry>
			<origin xyz="0.016617679345317184 -0.008678229100960968 0.0689803697615862" rpy="0 0 0"></origin>
		</collision>
	</link>
	<link name="left_outer_knuckle">
		<inertial>
			<origin rpy="0 0 0" xyz="2.9948E-14 0.021559 0.015181"></origin>
			<mass value="0.033618"></mass>
			<inertia ixx="1.9111E-05" ixy="-1.8803E-17" ixz="-1.1002E-17" iyy="6.6256E-06" iyz="-7.3008E-06" izz="1.3185E-05"></inertia>
		</inertial>
		<visual>
			<geometry>
				<mesh filename="package://meshes/left_outer_knuckle.stl"></mesh>
			</geometry>
			<origin rpy="0 0 0" xyz="0 0 0"></origin>
			<material name="Silver"></material>
		</visual>
		<collision>
			<geometry>
				<sphere radius="0.011853"></sphere>
			</geometry>
			<origin xyz="0.0 -0.015067236100256443 0.0001796849876195203" rpy="0 0 0"></origin>
		</collision>
		<collision>
			<geometry>
				<sphere radius="0.012303"></sphere>
			</geometry>
			<origin xyz="-1e-06 0.0015117638997435567 0.00021568498761951813" rpy="0 0 0"></origin>
		</collision>
		<collision>
			<geometry>
				<sphere radius="0.012781"></sphere>
			</geometry>
			<origin xyz="0.0 -0.0007442361002564426 0.01414968498761952" rpy="0 0 0"></origin>
		</collision>
		<collision>
			<geometry>
				<sphere radius="0.012789"></sphere>
			</geometry>
			<origin xyz="-1e-06 0.019739763899743558 0.00938968498761952" rpy="0 0 0"></origin>
		</collision>
		<collision>
			<geometry>
				<sphere radius="0.012798"></sphere>
			</geometry>
			<origin xyz="0.0 0.017105763899743557 0.02636468498761952" rpy="0 0 0"></origin>
		</collision>
		<collision>
			<geometry>
				<sphere radius="0.012957"></sphere>
			</geometry>
			<origin xyz="0.0 0.03727476389974356 0.01925968498761952" rpy="0 0 0"></origin>
		</collision>
		<collision>
			<geometry>
				<sphere radius="0.012143"></sphere>
			</geometry>
			<origin xyz="0.0 0.03265076389974356 0.03790068498761952" rpy="0 0 0"></origin>
		</collision>
		<collision>
			<geometry>
				<sphere radius="0.012211"></sphere>
			</geometry>
			<origin xyz="0.0 0.04309376389974356 0.02758468498761952" rpy="0 0 0"></origin>
		</collision>
	</link>
	<link name="left_finger">
		<inertial>
			<origin rpy="0 0 0" xyz="-2.4536E-14 -0.016413 0.029258"></origin>
			<mass value="0.048304"></mass>
			<inertia ixx="1.7493E-05" ixy="-4.2156E-19" ixz="6.9164E-18" iyy="1.7225E-05" iyz="4.6433E-06" izz="5.1466E-06"></inertia>
		</inertial>
		<visual>
			<geometry>
				<mesh filename="package://meshes/left_finger.stl"></mesh>
			</geometry>
			<origin rpy="0 0 0" xyz="0 0 0"></origin>
			<material name="Silver"></material>
		</visual>
		<collision>
			<geometry>
				<sphere radius="0.017782"></sphere>
			</geometry>
			<origin xyz="-0.000662 -0.005104536041975021 0.008066536349311471" rpy="0 0 0"></origin>
		</collision>
		<collision>
			<geometry>
				<sphere radius="0.020352"></sphere>
			</geometry>
			<origin xyz="-0.000586 -0.01447853604197502 0.02636953634931147" rpy="0 0 0"></origin>
		</collision>
		<collision>
			<geometry>
				<sphere radius="0.016208"></sphere>
			</geometry>
			<origin xyz="0.007385 -0.018859536041975024 0.046594536349311474" rpy="0 0 0"></origin>
		</collision>
		<collision>
			<geometry>
				<sphere radius="0.016199"></sphere>
			</geometry>
			<origin xyz="-0.006039 -0.018720536041975024 0.04738353634931147" rpy="0 0 0"></origin>
		</collision>
	</link>
	<link name="left_inner_knuckle">
		<inertial>
			<origin rpy="0 0 0" xyz="1.86600784687907E-06 0.0220467847633621 0.0261334672830885"></origin>
			<mass value="0.0230125781256706"></mass>
			<inertia ixx="6.09490024271906E-06" ixy="6.06651326160071E-11" ixz="7.19102670500635E-11" iyy="6.01955084375188E-06" iyz="-2.75316812991721E-06" izz="5.07862004479903E-06"></inertia>
		</inertial>
		<visual>
			<geometry>
				<mesh filename="package://meshes/left_inner_knuckle.stl"></mesh>
			</geometry>
			<origin rpy="0 0 0" xyz="0 0 0"></origin>
			<material name="Silver"></material>
		</visual>
		<collision>
			<geometry>
				<sphere radius="0.015388"></sphere>
			</geometry>
			<origin xyz="-0.008186169581969308 0.032766760799705794 0.038973682528031905" rpy="0 0 0"></origin>
		</collision>
		<collision>
			<geometry>
				<sphere radius="0.016501"></sphere>
			</geometry>
			<origin xyz="0.008438830418030691 0.0318617607997058 0.03794568252803191" rpy="0 0 0"></origin>
		</collision>
		<collision>
			<geometry>
				<sphere radius="0.016305"></sphere>
			</geometry>
			<origin xyz="-0.005778169581969308 0.019169760799705796 0.02286068252803191" rpy="0 0 0"></origin>
		</collision>
		<collision>
			<geometry>
				<sphere radius="0.016504"></sphere>
			</geometry>
			<origin xyz="-0.008879169581969309 0.004120760799705796 0.005218682528031905" rpy="0 0 0"></origin>
		</collision>
		<collision>
			<geometry>
				<sphere radius="0.015004"></sphere>
			</geometry>
			<origin xyz="0.005488830418030692 0.001168760799705796 0.0013956825280319052" rpy="0 0 0"></origin>
		</collision>
		<collision>
			<geometry>
				<sphere radius="0.016561"></sphere>
			</geometry>
			<origin xyz="0.008371830418030692 0.014714760799705795 0.01791268252803191" rpy="0 0 0"></origin>
		</collision>
	</link>
	<link name="right_outer_knuckle">
		<inertial>
			<origin rpy="0 0 0" xyz="-3.1669E-14 -0.021559 0.015181"></origin>
			<mass value="0.033618"></mass>
			<inertia ixx="1.9111E-05" ixy="-1.8789E-17" ixz="1.0986E-17" iyy="6.6256E-06" iyz="7.3008E-06" izz="1.3185E-05"></inertia>
		</inertial>
		<visual>
			<geometry>
				<mesh filename="package://meshes/right_outer_knuckle.stl"></mesh>
			</geometry>
			<origin rpy="0 0 0" xyz="0 0 0"></origin>
			<material name="Silver"></material>
		</visual>
		<collision>
			<geometry>
				<sphere radius="0.012305"></sphere>
			</geometry>
			<origin xyz="0.0 0.014558236100256444 0.00015068498761951904" rpy="0 0 0"></origin>
		</collision>
		<collision>
			<geometry>
				<sphere radius="0.012864"></sphere>
			</geometry>
			<origin xyz="0.0 -0.0031957638997435565 0.0007946849876195178" rpy="0 0 0"></origin>
		</collision>
		<collision>
			<geometry>
				<sphere radius="0.013272"></sphere>
			</geometry>
			<origin xyz="0.0 -0.0003447638997435571 0.01289668498761952" rpy="0 0 0"></origin>
		</collision>
		<collision>
			<geometry>
				<sphere radius="0.012649"></sphere>
			</geometry>
			<origin xyz="0.0 -0.021463763899743558 0.010271684987619519" rpy="0 0 0"></origin>
		</collision>
		<collision>
			<geometry>
				<sphere radius="0.013038"></sphere>
			</geometry>
			<origin xyz="0.0 -0.016499763899743558 0.027804684987619517" rpy="0 0 0"></origin>
		</collision>
		<collision>
			<geometry>
				<sphere radius="0.012503"></sphere>
			</geometry>
			<origin xyz="0.0 -0.03517076389974356 0.02153068498761952" rpy="0 0 0"></origin>
		</collision>
		<collision>
			<geometry>
				<sphere radius="0.012273"></sphere>
			</geometry>
			<origin xyz="0.0 -0.033558763899743556 0.03745868498761952" rpy="0 0 0"></origin>
		</collision>
		<collision>
			<geometry>
				<sphere radius="0.011822"></sphere>
			</geometry>
			<origin xyz="0.0 -0.04342776389974356 0.02693568498761952" rpy="0 0 0"></origin>
		</collision>
	</link>
	<link name="right_finger">
		<inertial>
			<origin rpy="0 0 0" xyz="2.5618E-14 0.016413 0.029258"></origin>
			<mass value="0.048304"></mass>
			<inertia ixx="1.7493E-05" ixy="-5.0014E-19" ixz="-7.5079E-18" iyy="1.7225E-05" iyz="-4.6435E-06" izz="5.1466E-06"></inertia>
		</inertial>
		<visual>
			<geometry>
				<mesh filename="package://meshes/right_finger.stl"></mesh>
			</geometry>
			<origin rpy="0 0 0" xyz="0 0 0"></origin>
			<material name="Silver"></material>
		</visual>
		<collision>
			<geometry>
				<sphere radius="0.017212"></sphere>
			</geometry>
			<origin xyz="-0.001351 0.004531536041975022 0.007150536349311471" rpy="0 0 0"></origin>
		</collision>
		<collision>
			<geometry>
				<sphere radius="0.020671"></sphere>
			</geometry>
			<origin xyz="-0.001143 0.014240536041975022 0.02497553634931147" rpy="0 0 0"></origin>
		</collision>
		<collision>
			<geometry>
				<sphere radius="0.017334"></sphere>
			</geometry>
			<origin xyz="-0.004558 0.018361536041975022 0.047095536349311476" rpy="0 0 0"></origin>
		</collision>
		<collision>
			<geometry>
				<sphere radius="0.017109"></sphere>
			</geometry>
			<origin xyz="0.007357 0.018685536041975023 0.04564653634931147" rpy="0 0 0"></origin>
		</collision>
	</link>
	<link name="right_inner_knuckle">
		<inertial>
			<origin rpy="0 0 0" xyz="1.866E-06 -0.022047 0.026133"></origin>
			<mass value="0.023013"></mass>
			<inertia ixx="6.0949E-06" ixy="-6.0665E-11" ixz="7.191E-11" iyy="6.0197E-06" iyz="2.7531E-06" izz="5.0784E-06"></inertia>
		</inertial>
		<visual>
			<geometry>
				<mesh filename="package://meshes/right_inner_knuckle.stl"></mesh>
			</geometry>
			<origin rpy="0 0 0" xyz="0 0 0"></origin>
			<material name="Silver"></material>
		</visual>
		<collision>
			<geometry>
				<sphere radius="0.015401"></sphere>
			</geometry>
			<origin xyz="0.006479061544579896 -0.032977792103220285 0.039116162119989" rpy="0 0 0"></origin>
		</collision>
		<collision>
			<geometry>
				<sphere radius="0.015583"></sphere>
			</geometry>
			<origin xyz="-0.008752938455420103 -0.03143879210322029 0.036937162119989" rpy="0 0 0"></origin>
		</collision>
		<collision>
			<geometry>
				<sphere radius="0.016206"></sphere>
			</geometry>
			<origin xyz="0.006589061544579896 -0.01919479210322029 0.022485162119989" rpy="0 0 0"></origin>
		</collision>
		<collision>
			<geometry>
				<sphere radius="0.01606"></sphere>
			</geometry>
			<origin xyz="-0.006751938455420103 -0.01551279210322029 0.018056162119989002" rpy="0 0 0"></origin>
		</collision>
		<collision>
			<geometry>
				<sphere radius="0.015485"></sphere>
			</geometry>
			<origin xyz="0.007577061544579896 -0.003932792103220289 0.004370162119989002" rpy="0 0 0"></origin>
		</collision>
		<collision>
			<geometry>
				<sphere radius="0.014706"></sphere>
			</geometry>
			<origin xyz="-0.005997938455420104 -0.002565792103220289 0.002778162119989002" rpy="0 0 0"></origin>
		</collision>
	</link>
	<link name="link_tcp"></link>
	<link name="Link_Zero_Point">
		<inertial>
			<origin xyz="0 0 0" rpy="0 0 0"></origin>
			<mass value="0.001"></mass>
			<inertia ixx="1e-9" ixy="0" ixz="0" iyy="1e-9" iyz="0" izz="1e-9"></inertia>
		</inertial>
	</link>
	<link name="Link_Virtual_X">
		<inertial>
			<origin xyz="0 0 0" rpy="0 0 0"></origin>
			<mass value="0.001"></mass>
			<inertia ixx="1e-9" ixy="0" ixz="0" iyy="1e-9" iyz="0" izz="1e-9"></inertia>
		</inertial>
	</link>
	<link name="Link_Virtual_Y">
		<inertial>
			<origin xyz="0 0 0" rpy="0 0 0"></origin>
			<mass value="0.001"></mass>
			<inertia ixx="1e-9" ixy="0" ixz="0" iyy="1e-9" iyz="0" izz="1e-9"></inertia>
		</inertial>
	</link>
	<link name="Link_Virtual_Theta">
		<inertial>
			<origin xyz="0 0 0" rpy="0 0 0"></origin>
			<mass value="0.001"></mass>
			<inertia ixx="1e-9" ixy="0" ixz="0" iyy="1e-9" iyz="0" izz="1e-9"></inertia>
		</inertial>
	</link>
	<joint name="FR_joint" type="fixed">
		<origin rpy="0 0 0" xyz="0.53412685915 -0.27255433797836304  0.12812547385692596"></origin>
		<parent link="base_link"></parent>
		<child link="front_right_1"></child>
	</joint>
	<joint name="FL_joint" type="fixed">
		<origin rpy="0 0 0" xyz="0.53412685915 0.27255433797836304  0.12812547385692596"></origin>
		<parent link="base_link"></parent>
		<child link="front_left_1"></child>
	</joint>
	<joint name="BR_joint" type="fixed">
		<origin rpy="0 0 0" xyz="0 -0.250498  0.12285605818033218"></origin>
		<parent link="base_link"></parent>
		<child link="back_right_1"></child>
	</joint>
	<joint name="BL_joint" type="fixed">
		<origin rpy="0 0 0" xyz="0 0.250498  0.12285605818033218"></origin>
		<parent link="base_link"></parent>
		<child link="back_left_1"></child>
	</joint>
	<joint name="world_joint" type="fixed">
		<parent link="base_link"></parent>
		<child link="link_base"></child>
		<origin rpy="0 -0.0436332 0" xyz="0.385 0.285 0.658"></origin>
	</joint>
	<joint name="joint1" type="revolute">
		<origin rpy="0 0 0" xyz="0 0 0.267"></origin>
		<parent link="link_base"></parent>
		<child link="link1"></child>
		<axis xyz="0 0 1"></axis>
		<limit effort="50" lower="-6.283185307179586" upper="6.283185307179586" velocity="3.14"></limit>
		<dynamics damping="10" friction="1"></dynamics>
	</joint>
	<joint name="joint2" type="revolute">
		<origin rpy="-1.5708 0 0" xyz="0 0 0"></origin>
		<parent link="link1"></parent>
		<child link="link2"></child>
		<axis xyz="0 0 1"></axis>
		<limit effort="50" lower="-2.059" upper="2.0944" velocity="3.14"></limit>
		<dynamics damping="10" friction="1"></dynamics>
	</joint>
	<joint name="joint3" type="revolute">
		<origin rpy="1.5708 0 0" xyz="0 -0.293 0"></origin>
		<parent link="link2"></parent>
		<child link="link3"></child>
		<axis xyz="0 0 1"></axis>
		<limit effort="30" lower="-6.283185307179586" upper="6.283185307179586" velocity="3.14"></limit>
		<dynamics damping="5" friction="1"></dynamics>
	</joint>
	<joint name="joint4" type="revolute">
		<origin rpy="1.5708 0 0" xyz="0.0525 0 0"></origin>
		<parent link="link3"></parent>
		<child link="link4"></child>
		<axis xyz="0 0 1"></axis>
		<limit effort="30" lower="-0.19198" upper="3.927" velocity="3.14"></limit>
		<dynamics damping="5" friction="1"></dynamics>
	</joint>
	<joint name="joint5" type="revolute">
		<origin rpy="1.5708 0 0" xyz="0.0775 -0.3425 0"></origin>
		<parent link="link4"></parent>
		<child link="link5"></child>
		<axis xyz="0 0 1"></axis>
		<limit effort="30" lower="-6.283185307179586" upper="6.283185307179586" velocity="3.14"></limit>
		<dynamics damping="5" friction="1"></dynamics>
	</joint>
	<joint name="joint6" type="revolute">
		<origin rpy="1.5708 0 0" xyz="0 0 0"></origin>
		<parent link="link5"></parent>
		<child link="link6"></child>
		<axis xyz="0 0 1"></axis>
		<limit effort="20" lower="-1.69297" upper="3.141592653589793" velocity="3.14"></limit>
		<dynamics damping="2" friction="1"></dynamics>
	</joint>
	<joint name="joint7" type="revolute">
		<origin rpy="-1.5708 0 0" xyz="0.076 0.097 0"></origin>
		<parent link="link6"></parent>
		<child link="link7"></child>
		<axis xyz="0 0 1"></axis>
		<limit effort="20" lower="-6.283185307179586" upper="6.283185307179586" velocity="3.14"></limit>
		<dynamics damping="2" friction="1"></dynamics>
	</joint>
	<joint name="joint_eef" type="fixed">
		<origin rpy="0 0 0" xyz="0 0 0"></origin>
		<parent link="link7"></parent>
		<child link="link_eef"></child>
	</joint>
	<joint name="gripper_fix" type="fixed">
		<parent link="link_eef"></parent>
		<child link="xarm_gripper_base_link"></child>
		<origin rpy="0 0 0" xyz="0 0 0"></origin>
	</joint>
	<joint name="drive_joint" type="fixed">
		<origin rpy="0 0 0" xyz="0 0.035 0.059098"></origin>
		<parent link="xarm_gripper_base_link"></parent>
		<child link="left_outer_knuckle"></child>
	</joint>
	<joint name="left_finger_joint" type="fixed">
		<origin rpy="0 0 0" xyz="0 0.035465 0.042039"></origin>
		<parent link="left_outer_knuckle"></parent>
		<child link="left_finger"></child>
	</joint>
	<joint name="left_inner_knuckle_joint" type="fixed">
		<origin rpy="0 0 0" xyz="0 0.02 0.074098"></origin>
		<parent link="xarm_gripper_base_link"></parent>
		<child link="left_inner_knuckle"></child>
	</joint>
	<joint name="right_outer_knuckle_joint" type="fixed">
		<origin rpy="0 0 0" xyz="0 -0.035 0.059098"></origin>
		<parent link="xarm_gripper_base_link"></parent>
		<child link="right_outer_knuckle"></child>
	</joint>
	<joint name="right_finger_joint" type="fixed">
		<origin rpy="0 0 0" xyz="0 -0.035465 0.042039"></origin>
		<parent link="right_outer_knuckle"></parent>
		<child link="right_finger"></child>
	</joint>
	<joint name="right_inner_knuckle_joint" type="fixed">
		<origin rpy="0 0 0" xyz="0 -0.02 0.074098"></origin>
		<parent link="xarm_gripper_base_link"></parent>
		<child link="right_inner_knuckle"></child>
	</joint>
	<joint name="joint_tcp" type="fixed">
		<origin rpy="0 0 0" xyz="0 0 0.172"></origin>
		<parent link="xarm_gripper_base_link"></parent>
		<child link="link_tcp"></child>
	</joint>
	<joint name="Joint_Virtual_X" type="prismatic">
		<origin xyz="0 0 0" rpy="0 0 0"></origin>
		<parent link="Link_Zero_Point"></parent>
		<child link="Link_Virtual_X"></child>
		<axis xyz="1 0 0"></axis>
		<limit lower="-10" upper="10" effort="100" velocity="1.0"></limit>
	</joint>
	<joint name="Joint_Virtual_Y" type="prismatic">
		<origin xyz="0 0 0" rpy="0 0 0"></origin>
		<parent link="Link_Virtual_X"></parent>
		<child link="Link_Virtual_Y"></child>
		<axis xyz="0 1 0"></axis>
		<limit lower="-10" upper="10" effort="100" velocity="1.0"></limit>
	</joint>
	<joint name="Joint_Virtual_Theta" type="revolute">
		<origin xyz="0 0 0" rpy="0 0 0"></origin>
		<parent link="Link_Virtual_Y"></parent>
		<child link="Link_Virtual_Theta"></child>
		<axis xyz="0 0 1"></axis>
		<limit lower="-3.141592653589793" upper="3.141592653589793" effort="100" velocity="1.0"></limit>
	</joint>
	<joint name="Joint_Base_Fixed" type="fixed">
		<origin xyz="0 0 0" rpy="0 0 0"></origin>
		<parent link="Link_Virtual_Theta"></parent>
		<child link="base_link"></child>
	</joint>
</robot>
